https://discourse.onlinedegree.iitm.ac.in/t/163247

You actually need to make the request to get the answer."</p><hr>

<h4>22f3002723 (#87)</h4>
<p>For question 1 getting the below response … not sure what it means<br/>
ythonError: Traceback (most recent call last): File “/lib/python312.zip/_pyodide/_base.py”, line 523, in eval_code .run(globals, locals) ^^^^^^^^^^^^^^^^^^^^ File “/lib/python312.zip/_pyodide/_base.py”, line 357, in run coroutine = eval(self.code, globals, locals) ^^^^^^^^^^^^^^^^^^^^^^^^^^^^^^^^ File “”, line 53, in  TypeError: unhashable type: ‘dict’</p><hr>

<h4>Sudhishnarayan (#86)</h4>
<p>This is regarding the 8th question. Same here, I am getting the answer for all the test cases, but then also, I am getting error in the portal while saving. Please help me out here.