https://discourse.onlinedegree.iitm.ac.in/t/171141

Its misconfigured.<br/>
This is the error when building it:</p>
<pre><code class="lang-auto">=&gt; ERROR [8/8] COPY .env /app/                                                                                                                         0.0s
------
 &gt; [8/8] COPY .env /app/:
------
Dockerfile:20
--------------------
  18 |     # Copy application files
  19 |     COPY *.py /app/
  20 | &gt;&gt;&gt; COPY .env /app/
  21 |     
  22 |     # Explicitly set the correct binary path and use `sh -c`
--------------------
ERROR: failed to solve: failed to compute cache key: failed to calculate checksum of ref 468faeeb-6d46-4aeb-a590-25bae24a84d5::y52oingx9lezoq9kjiwp6v58m: "/.env": not found
</code></pre>
<p><div class="lightbox-wrapper"><a class="lightbox" data-download-href="/uploads/short-url/iWIIlgMm6iiSN3X2eus14cfi7sL.png?dl=1" href="https://europe1.discourse-cdn.com/flex013/uploads/iitm/original/3X/8/4/84ca6c44a889d9afdd688d56fd169d99cb74a573.png" title="Screenshot 2025-04-08 at 11.12.18 am"><div class="meta"><svg aria-hidden="true" class="fa d-icon d-icon-far-image svg-icon"><use href="#far-image"></use></svg><span class="filename">Screenshot 2025-04-08 at 11.12.18 am</span><span class="informations">754×302 41 KB</span><svg aria-hidden="true" class="fa d-icon d-icon-discourse-expand svg-icon"><use href="#discourse-expand"></use></svg></div></a></div></p>
<p>This is because if you look at your Dockerfile .env does not exist in your repo.<br/>
Therefore it does not build.<br/>
Your docker is supposed to take the AIPROXY token from our environment not from yours.<br/>
This is passed dynamically at runtime of the Docker.</p>
<p>Since it fails to build, we cannot evaluate it.</p>
<p>Kind regards</p><hr>

<h4>22f3000819 (#432)</h4>
<p><a class="mention" href="/u/carlton">@carlton</a> <a class="mention" href="/u/jivraj">@Jivraj</a><br/>
Sir, in my docker logs, the datagen script encounters error during creating the credit card image for A8 during which it fails to find both the fonts used in the try and except blocks, resulting in the datagen script to stop abruptly without creating the files for A8 to A10.</p>
<p><div class="lightbox-wrapper"><a class="lightbox" data-download-href="/uploads/short-url/nuja8ivRzao9XSmkZlLA9RYFAsP.png?dl=1" href="https://europe1.discourse-cdn.com/flex013/uploads/iitm/original/3X/a/4/a49f182e22015df35039be85cdd26ad71a07f7a3.png" rel="noopener nofollow ugc" title="image"><div class="meta"><svg aria-hidden="true" class="fa d-icon d-icon-far-image svg-icon"><use href="#far-image"></use></svg><span class="filename">image</span><span class="informations">1298×857 29.4 KB</span><svg aria-hidden="true" class="fa d-icon d-icon-discourse-expand svg-icon"><use href="#discourse-expand"></use></svg></div></a></div></p>
<p>I actually want to know if this could have been avoided by some changes in my code or is it an issue in the datagen.py script, because as the situation currently stands, my app wasn’t even tested properly for tasks A8 to A10 as the datagen.py script failed to create the required files because it could not find a font which as far as I knew was not specified that it must be included in my own code or image somehow.</p>
<p>Edit 1: I just realized that the datagen script looked for the fonts in python 3.13/site-packages/…<br/>
But my docker image is using the python:3.12-slim-bookworm.